Some weights of the model checkpoint at bert-base-uncased were not used when initializing BertForSequenceClassification: ['cls.predictions.transform.LayerNorm.bias', 'cls.predictions.transform.LayerNorm.weight', 'cls.seq_relationship.weight', 'cls.seq_relationship.bias', 'cls.predictions.transform.dense.bias', 'cls.predictions.transform.dense.weight', 'cls.predictions.decoder.weight', 'cls.predictions.bias']
- This IS expected if you are initializing BertForSequenceClassification from the checkpoint of a model trained on another task or with another architecture (e.g. initializing a BertForSequenceClassification model from a BertForPreTraining model).
- This IS NOT expected if you are initializing BertForSequenceClassification from the checkpoint of a model that you expect to be exactly identical (initializing a BertForSequenceClassification model from a BertForSequenceClassification model).
Some weights of BertForSequenceClassification were not initialized from the model checkpoint at bert-base-uncased and are newly initialized: ['classifier.weight', 'classifier.bias']
You should probably TRAIN this model on a down-stream task to be able to use it for predictions and inference.
Traceback (most recent call last):
  File "/tmp/loizeaua-34075/NLP-Sentiment-Analysis/src/tester.py", line 86, in <module>
    devacc, testacc = train_and_eval(classifier, trainfile, devfile, testfile, i, device)
  File "/tmp/loizeaua-34075/NLP-Sentiment-Analysis/src/tester.py", line 46, in train_and_eval
    classifier.train(trainfile, devfile, device)
  File "/tmp/loizeaua-34075/NLP-Sentiment-Analysis/src/classifier.py", line 72, in train
    train_inputs, train_polarities = load_data( os.getcwd()+"/"+ train_filename, self.tokenizer)
  File "/tmp/loizeaua-34075/NLP-Sentiment-Analysis/src/classifier.py", line 16, in load_data
    df = pd.read_csv(filename, sep='\t', header=None, names=['polarity', 'aspect', 'term', 'offset', 'sentence'])
  File "/usr/users/xai_boundingboxes/loizeaua/.conda/envs/nlp/lib/python3.9/site-packages/pandas/util/_decorators.py", line 211, in wrapper
    return func(*args, **kwargs)
  File "/usr/users/xai_boundingboxes/loizeaua/.conda/envs/nlp/lib/python3.9/site-packages/pandas/util/_decorators.py", line 331, in wrapper
    return func(*args, **kwargs)
  File "/usr/users/xai_boundingboxes/loizeaua/.conda/envs/nlp/lib/python3.9/site-packages/pandas/io/parsers/readers.py", line 950, in read_csv
    return _read(filepath_or_buffer, kwds)
  File "/usr/users/xai_boundingboxes/loizeaua/.conda/envs/nlp/lib/python3.9/site-packages/pandas/io/parsers/readers.py", line 605, in _read
    parser = TextFileReader(filepath_or_buffer, **kwds)
  File "/usr/users/xai_boundingboxes/loizeaua/.conda/envs/nlp/lib/python3.9/site-packages/pandas/io/parsers/readers.py", line 1442, in __init__
    self._engine = self._make_engine(f, self.engine)
  File "/usr/users/xai_boundingboxes/loizeaua/.conda/envs/nlp/lib/python3.9/site-packages/pandas/io/parsers/readers.py", line 1735, in _make_engine
    self.handles = get_handle(
  File "/usr/users/xai_boundingboxes/loizeaua/.conda/envs/nlp/lib/python3.9/site-packages/pandas/io/common.py", line 856, in get_handle
    handle = open(
FileNotFoundError: [Errno 2] No such file or directory: '/tmp/loizeaua-34075/NLP-Sentiment-Analysis/../data/traindata.csv'
rsync: link_stat "/tmp/loizeaua-34075/NLP-Sentiment-Analysis/models/*" failed: No such file or directory (2)
rsync error: some files/attrs were not transferred (see previous errors) (code 23) at main.c(1207) [sender=3.1.3]
